<?xml version="1.0"?>
<robot name="hospital_robot">
  <!-- Define materials -->
  <material name="gray">
    <color rgba="0.5 0.5 0.5 1.0"/>
  </material>
  <material name="black">
    <color rgba="0 0 0 1"/>
  </material>

  <!-- Base link of the robot -->
  <link name="base_link">
    <inertial>
      <mass value="0.5"/>
      <origin xyz="0 0 0.1"/>
      <inertia ixx="0.01" ixy="0.0" ixz="0.0" iyy="0.01" iyz="0.0" izz="0.01"/>
    </inertial>
    <visual>
      <origin xyz="0 0 0.1"/>
      <geometry>
        <box size="0.6 0.4 0.2"/>
      </geometry>
      <material name="gray"/>
    </visual>
    <collision>
      <origin xyz="0 0 0.1"/>
      <geometry>
        <box size="0.6 0.4 0.2"/>
      </geometry>
    </collision>
  </link>

  <!-- Base footprint joint -->
  <joint name="base_footprint_joint" type="fixed">
    <parent link="base_link"/>
    <child link="base_footprint"/>
    <origin xyz="0 0 0.1" rpy="0 0 0"/>
  </joint>
  <link name="base_footprint"/>

  <!-- Left wheel link -->
  <link name="left_wheel">
    <inertial>
      <mass value="1.0"/>
      <origin xyz="0 0 0"/>
      <inertia ixx="0.001" ixy="0.0" ixz="0.0" iyy="0.001" iyz="0.0" izz="0.001"/>
    </inertial>
    <visual>
      <origin xyz="0 0 0" rpy="1.57 0 0"/>
      <geometry>
        <cylinder length="0.05" radius="0.1"/>
      </geometry>
      <material name="black"/>
    </visual>
    <collision>
      <origin xyz="0 0 0" rpy="1.57 0 0"/>
      <geometry>
        <cylinder length="0.05" radius="0.1"/>
      </geometry>
    </collision>
  </link>

  <!-- Right wheel link -->
  <link name="right_wheel">
    <inertial>
      <mass value="1.0"/>
      <origin xyz="0 0 0"/>
      <inertia ixx="0.001" ixy="0.0" ixz="0.0" iyy="0.001" iyz="0.0" izz="0.001"/>
    </inertial>
    <visual>
      <origin xyz="0 0 0" rpy="1.57 0 0"/>
      <geometry>
        <cylinder length="0.05" radius="0.1"/>
      </geometry>
      <material name="black"/>
    </visual>
    <collision>
      <origin xyz="0 0 0" rpy="1.57 0 0"/>
      <geometry>
        <cylinder length="0.05" radius="0.1"/>
      </geometry>
    </collision>
  </link>

  <!-- Caster wheel link -->
  <link name="caster_wheel">
    <inertial>
      <mass value="0.5"/>
      <origin xyz="0 0 0"/>
      <inertia ixx="0.0005" ixy="0.0" ixz="0.0" iyy="0.0005" iyz="0.0" izz="0.0005"/>
    </inertial>
    <visual>
      <origin xyz="0 0 0"/>
      <geometry>
        <sphere radius="0.05"/>
      </geometry>
      <material name="black"/>
    </visual>
    <collision>
      <origin xyz="0 0 0"/>
      <geometry>
        <sphere radius="0.05"/>
      </geometry>
    </collision>
  </link>

  <!-- LiDAR sensor -->
  <link name="lidar_link">
    <visual>
      <geometry>
        <cylinder length="0.05" radius="0.1"/>
      </geometry>
      <material name="black"/>
    </visual>
    <collision>
      <geometry>
        <cylinder length="0.225" radius="0.1"/>
      </geometry>
    </collision>
  </link>

  <!-- LiDAR joint -->
  <joint name="lidar_joint" type="fixed">
    <parent link="base_link"/>
    <child link="lidar_link"/>
    <origin xyz="0.2 0 0.225" rpy="0 0 0"/>
  </joint>

  <!-- Left wheel joint -->
  <joint name="left_wheel_joint" type="continuous">
    <parent link="base_link"/>
    <child link="left_wheel"/>
    <origin xyz="-0.15 0.225 0" rpy="0 0 0"/>
    <axis xyz="0 1 0"/>
  </joint>

  <!-- Right wheel joint -->
  <joint name="right_wheel_joint" type="continuous">
    <parent link="base_link"/>
    <child link="right_wheel"/>
    <origin xyz="-0.15 -0.225 0" rpy="0 0 0"/>
    <axis xyz="0 1 0"/>
  </joint>

  <!-- Caster wheel joint -->
  <joint name="caster_wheel_joint" type="fixed">
    <parent link="base_link"/>
    <child link="caster_wheel"/>
    <origin xyz="0.2 0 -0.05" rpy="0 0 0"/>
  </joint>

  <!-- Gazebo plugin for differential drive -->
  <gazebo>
    <plugin name="gazebo_ros_diff_drive" filename="libgazebo_ros_diff_drive.so">
      <!-- Namespace and remapping -->
      <ros>
        <namespace>/</namespace>
        <remapping>cmd_vel:=/cmd_vel</remapping>
      </ros>

      <!-- Wheel info -->
      <left_joint>left_wheel_joint</left_joint>
      <right_joint>right_wheel_joint</right_joint>
      <wheel_separation>0.5</wheel_separation>
      <wheel_diameter>0.2</wheel_diameter>

      <!-- Limits -->
      <max_wheel_torque>200</max_wheel_torque>
      <max_wheel_acceleration>10.0</max_wheel_acceleration>

      <!-- Output -->
      <odometry_frame>odom</odometry_frame>
      <robot_base_frame>base_link</robot_base_frame>

      <!-- Publishing options -->
      <publish_odom>true</publish_odom>
      <publish_odom_tf>true</publish_odom_tf>
      <publish_wheel_tf>true</publish_wheel_tf>
    </plugin>
  </gazebo>

  <!-- Gazebo sensor plugin for LiDAR -->
  <gazebo reference="lidar_link">
    <sensor name="lidar" type="ray">
      <always_on>true</always_on>
      <visualize>true</visualize>
      <update_rate>10</update_rate>
      <ray>
        <scan>
          <horizontal>
            <samples>720</samples>
            <resolution>1.000000</resolution>
            <min_angle>0</min_angle>
            <max_angle>6.28</max_angle>
          </horizontal>
        </scan>
        <range>
          <min>0.3</min>
          <max>15.0</max>
          <resolution>0.015</resolution>
        </range>
        <noise>
          <type>gaussian</type>
          <mean>0.0</mean>
          <stddev>0.01</stddev>
        </noise>
      </ray>
      <plugin name="scan" filename="libgazebo_ros_ray_sensor.so">
        <ros>
          <remapping>~/out:=scan</remapping>
        </ros>
        <output_type>sensor_msgs/LaserScan</output_type>
        <frame_name>lidar_link</frame_name>
      </plugin>
    </sensor>
  </gazebo>
</robot>

