<?xml version="1.0"?>
<robot name="hospital_robot">
  <!-- Define materials -->
  <material name="gray">
    <color rgba="0.7 0.7 0.7 1"/>
  </material>
  <material name="black">
    <color rgba="0.00 0.59 0.53 1"/>
  </material>
  <material name="purple">
    <color rgba="0.5 0 0.5 1"/>
  </material>


  <!-- Base footprint link -->
  <link name="base_footprint"/>



  <!-- Base link of the robot -->
  <link name="base_link">
    <visual>
      <origin xyz="0 0 0.1"/>
      <geometry>
        <box size="0.6 0.4 0.2"/>
      </geometry>
      <material name="gray"/>
    </visual>
  </link>
  
  <!-- Odom frame -->


  <!-- Joint between base_footprint and base_link -->
  <joint name="base_footprint_joint" type="fixed">
    <parent link="base_link"/>
    <child link="base_footprint"/>
    <origin xyz="0 0 0.1" rpy="0 0 0"/>
  </joint>

  <!-- Left wheel link -->
  <link name="left_wheel">
    <visual>
      <origin xyz="0 0 0" rpy="1.57 0 0"/>
      <geometry>
        <cylinder length="0.05" radius="0.12"/>
      </geometry>
      <material name="black"/>
    </visual>
  </link>

  <!-- Right wheel link -->
  <link name="right_wheel">
    <visual>
      <origin xyz="0 0 0" rpy="1.57 0 0"/>
      <geometry>
        <cylinder length="0.05" radius="0.12"/>
      </geometry>
      <material name="black"/>
    </visual>
  </link>

  <!-- Left wheel joint -->
  <joint name="left_wheel_joint" type="continuous">
    <parent link="base_link"/>
    <child link="left_wheel"/>
    <origin xyz="0 0.225 0.1" rpy="0 0 0"/>
    <axis xyz="0 1 0"/>
  </joint>

  <!-- Right wheel joint -->
  <joint name="right_wheel_joint" type="continuous">
    <parent link="base_link"/>
    <child link="right_wheel"/>
    <origin xyz="0 -0.225 0.1" rpy="0 0 0"/>
    <axis xyz="0 1 0"/>
  </joint>


  <!-- LiDAR sensor -->
  <link name="laser">
    <visual>
      <geometry>
        <cylinder length="0.05" radius="0.1"/>
      </geometry>
      <material name="purple"/>
    </visual>
  </link>
 
  <!-- LiDAR joint -->
  <joint name="lidar_joint" type="fixed">
    <parent link="base_link"/>
    <child link="laser"/>
    <origin xyz="0.2 0 0.225" rpy="0 0 0"/>
  </joint>

  <!-- Castor wheel link (optional) -->
  <link name="castor_wheel">
    <visual>
      <origin xyz="0 0 0" rpy="1.57 0 0"/>
      <geometry>
        <sphere radius="0.05"/>
      </geometry>
      <material name="black"/>
    </visual>
  </link>

  <!-- Castor wheel joint (optional) -->
  <joint name="castor_wheel_joint" type="fixed">
    <parent link="base_link"/>
    <child link="castor_wheel"/>
    <origin xyz="0.3 0 0.05" rpy="0 0 0"/>
  </joint>
</robot>
